Workbook

Sheet 2026 Özel Günler
A1: Özel Günler ve Resmi Tatiller
A3: Tarih | B3: Özel Günler | C3: Resmi Tatil | D3: Ay
A4: 1.01. | B4: Yeni Yıl | C4: Resmi Tatil | D4: Ocak
A5: 46024 | B5: Bilim Kurgu Günü | C5: — | D5: Ocak
A6: 46032 | B6: Dünya Gazeteciler Günü, Ziraat Mühendisleri Günü | C6: — | D6: Ocak
A8: 46038 | B8: Dünya Hijyen Günü | C8: — | D8: Ocak
A9: 46043 | B9: Dünya Sarılma Günü | C9: — | D9: Ocak
A10: 46046 | B10: Dünya Karşılıksız İyilik Günü | C10: — | D10: Ocak
A11: 24 – 31 Ocak | B11: Dünya Cüzzam Haftası | C11: — | D11: Ocak
A12: 46048 | B12: Uluslararası Gümrük Günü | C12: — | D12: Ocak
A13: 46050 | B13: Veri Koruma Günü | C13: — | D13: Ocak
A15: 46057 | B15: Dünya Kanser Günü | C15: — | D15: Şubat
A16: 46062 | B16: Dünya Sigarayı Bırakma Günü, Dünya Pizza Günü | C16: — | D16: Şubat
A18: 46066 | B18: Dünya Radyo Günü | C18: — | D18: Şubat
A19: 46067 | B19: Sevgililer Günü, Dünya Öykü Günü | C19: — | D19: Şubat
A20: 46070 | B20: Dünya Kediler Günü | C20: — | D20: Şubat
A21: 46080 | B21: Dünya Ressamlar Günü | C21: — | D21: Şubat
A22: 46081 | B22: Sivil Savunma Günü | C22: — | D22: Şubat
A23: 1 – 7 Mart | B23: Yeşilay Haftası, Deprem Haftası, Girişimcilik Haftası | C23: — | D23: Mart
A24: 46089 | B24: Dünya Kadınlar Günü | C24: — | D24: Mart
A25: 8 – 14 Mart | B25: Bilim ve Teknoloji Haftası | C25: — | D25: Mart
A26: 46093 | B26: İstiklal Marşı’nın Kabulü ve Mehmet Akif Ersoy’u Anma Günü | C26: — | D26: Mart
A27: 46095 | B27: Tıp Bayramı | C27: — | D27: Mart
A29: 46099 | B29: Çanakkale Zaferi | C29: — | D29: Mart
A30: 18-24 Mart | B30: Yaşlılara Saygı Haftası | C30: — | D30: Mart
A33: 46102 | B33: Nevruz Bayramı | C33: — | D33: Mart
A34: 46102 | B34: Dünya Down Sendromu Farkındalık Günü | C34: — | D34: Mart
A35: 46102 | B35: Dünya Şiir Günü | C35: — | D35: Mart
A36: 46102 | B36: Dünya Ormancılık Günü | C36: — | D36: Mart
A37: 21 – 26 Mart | B37: Orman Haftası | C37: — | D37: Mart
A38: 46103 | B38: Dünya Su Günü | C38: — | D38: Mart
A39: 46104 | B39: Dünya Meteoroloji Günü | C39: — | D39: Mart
A40: 46108 | B40: Dünya Tiyatrolar Günü | C40: — | D40: Mart
A41: 27 Mart – 2 Nisan | B41: Kütüphane Haftası | C41: — | D41: Mart
A42: 46113 | B42: Dünya Şaka Günü | C42: — | D42: Nisan
A43: 1 – 7 Nisan | B43: Kanserle Savaş Haftası | C43: — | D43: Nisan
A44: 46114 | B44: Dünya Otizm Farkındalık Günü | C44: — | D44: Nisan
A45: 46116 | B45: Dünya Sokak Hayvanları Günü | C45: — | D45: Nisan
A46: 46119 | B46: Kişisel Verileri Koruma Günü | C46: — | D46: Nisan
A47: 7 – 13 Nisan | B47: Dünya Sağlık Haftası, Sağlık ve Sosyal Güvenlik Haftası | C47: — | D47: Nisan
...

Sheet 2026 Resmi Tatiller
A1: 2026 Resmi Tatiller
A2: Avansas “2026 Resmi Tatiller” tablosu (kaynak sitedeki ikinci tablo)
A3: Tarih | B3: Gün | C3: Özel Günler
A4: 1 Ocak 2026 | B4: Perşembe | C4: Yeni Yıl
A5: 19 Mart 2026 | B5: Perşembe | C5: Ramazan Bayramı Arifesi (Yarım Gün)
A6: 20 Mart -22 Mart 2026 | B6: Cuma – Pazar | C6: Ramazan Bayramı
A7: 23 Nisan 2026 | B7: Perşembe | C7: Ulusal Egemenlik ve Çocuk Bayramı
A8: 1 Mayıs 2026 | B8: Cuma | C8: İşçi Bayramı
A9: 19 Mayıs 2026 | B9: Salı | C9: Atatürk’ü Anma Gençlik ve Spor Bayramı
A10: 26 Mayıs 2026 | B10: Salı | C10: Kurban Bayramı Arefesi
A11: 27-30 Mayıs 2026 | B11: Çarşamba – Cumartesi | C11: Kurban Bayramı
A12: 15 Temmuz 2026 | B12: Çarşamba | C12: Demokrasi ve Milli Birlik Günü
A13: 30 Ağustos 2026 | B13: Pazar | C13: Zafer Bayramı
A14: 29 Ekim 2026 | B14: Perşembe | C14: Cumhuriyet Bayramı
A16: Not: Avansas resmi tatiller tablosunda 28 Ekim Cumhuriyet Bayramı arifesi (yarım gün) ayrı satır olarak yer almıyor. 2429 sayılı Kanun’a göre 28 Ekim öğleden sonra da resmi tatildir.

Sheet Özet
A1: 2026 — Ay Bazında Özet
A3: Ay | B3: Kayıt sayısı | C3: Resmi tatil kaydı
A4: Ocak | B4: =COUNTIF('2026 Özel Günler'!D$4:D$129,A4) -> 9 | C4: =COUNTIFS('2026 Özel Günler'!D$4:D$129,A4,'2026 Özel Günler'!C$4:C$129,"*Resmi Tatil*") -> 1
A5: Şubat | B5: =COUNTIF('2026 Özel Günler'!D$4:D$129,A5) -> 7 | C5: =COUNTIFS('2026 Özel Günler'!D$4:D$129,A5,'2026 Özel Günler'!C$4:C$129,"*Resmi Tatil*") -> 0
A6: Mart | B6: =COUNTIF('2026 Özel Günler'!D$4:D$129,A6) -> 16 | C6: =COUNTIFS('2026 Özel Günler'!D$4:D$129,A6,'2026 Özel Günler'!C$4:C$129,"*Resmi Tatil*") -> 0
A7: Nisan | B7: =COUNTIF('2026 Özel Günler'!D$4:D$129,A7) -> 13 | C7: =COUNTIFS('2026 Özel Günler'!D$4:D$129,A7,'2026 Özel Günler'!C$4:C$129,"*Resmi Tatil*") -> 1
A8: Mayıs | B8: =COUNTIF('2026 Özel Günler'!D$4:D$129,A8) -> 13 | C8: =COUNTIFS('2026 Özel Günler'!D$4:D$129,A8,'2026 Özel Günler'!C$4:C$129,"*Resmi Tatil*") -> 2
A9: Haziran | B9: =COUNTIF('2026 Özel Günler'!D$4:D$129,A9) -> 6 | C9: =COUNTIFS('2026 Özel Günler'!D$4:D$129,A9,'2026 Özel Günler'!C$4:C$129,"*Resmi Tatil*") -> 0
A10: Temmuz | B10: =COUNTIF('2026 Özel Günler'!D$4:D$129,A10) -> 12 | C10: =COUNTIFS('2026 Özel Günler'!D$4:D$129,A10,'2026 Özel Günler'!C$4:C$129,"*Resmi Tatil*") -> 1
A11: Ağustos | B11: =COUNTIF('2026 Özel Günler'!D$4:D$129,A11) -> 4 | C11: =COUNTIFS('2026 Özel Günler'!D$4:D$129,A11,'2026 Özel Günler'!C$4:C$129,"*Resmi Tatil*") -> 1
A12: Eylül | B12: =COUNTIF('2026 Özel Günler'!D$4:D$129,A12) -> 8 | C12: =COUNTIFS('2026 Özel Günler'!D$4:D$129,A12,'2026 Özel Günler'!C$4:C$129,"*Resmi Tatil*") -> 0
A13: Ekim | B13: =COUNTIF('2026 Özel Günler'!D$4:D$129,A13) -> 10 | C13: =COUNTIFS('2026 Özel Günler'!D$4:D$129,A13,'2026 Özel Günler'!C$4:C$129,"*Resmi Tatil*") -> 1
A14: Kasım | B14: =COUNTIF('2026 Özel Günler'!D$4:D$129,A14) -> 9 | C14: =COUNTIFS('2026 Özel Günler'!D$4:D$129,A14,'2026 Özel Günler'!C$4:C$129,"*Resmi Tatil*") -> 0
A15: Aralık | B15: =COUNTIF('2026 Özel Günler'!D$4:D$129,A15) -> 8 | C15: =COUNTIFS('2026 Özel Günler'!D$4:D$129,A15,'2026 Özel Günler'!C$4:C$129,"*Resmi Tatil*") -> 0
A16: Toplam | B16: =SUM(B4:B15) -> 115 | C16: =SUM(C4:C15) -> 7
